Workbook

Sheet 报价单
A1: AI 智能体落地交付项目 报 价 单
A2: 报价编号 | B2: QT-2026-1023-01 | C2: 报价日期 | D2: 46318 | E2: 有效期 | F2: 30 天
A3: 客户名称 | B3: （甲方全称） | C3: 项目名称 | D3: （项目全称，与合同一致）
A5: 一、基础费 交付能力（九个成本科目逐项对应，均可核验）
A6: 序号 | B6: 报价条目 | C6: 交付内容与范围 | D6: 计价方式 | E6: 金额（元） | F6: 备注
A7: 1 | B7: 售前调研与方案投入 | C7: 需求调研、方案与投标材料、POC 演示；含未中标情形的成本摊入 | D7: 一次性 | E7: ='成本测算'!$G$24/(1-'参数'!$B$9) -> 33040 | F7: 不因中标结果单独计费
A8: 2 | B8: 现状诊断与场景梳理 | C8: 现有流程卡点诊断、AI 可落地场景筛选与优先级排序，输出场景清单 | D8: 一次性 | E8: ='成本测算'!$G$25/(1-'参数'!$B$9) -> 39648 | F8: 定性结论亦计入交付物
A9: 3 | B9: 方案与架构设计 | C9: 技术选型、数据流设计、权限与安全架构、评测集（Golden Set）设计、验收标准定义 | D9: 一次性 | E9: ='成本测算'!$G$26/(1-'参数'!$B$9) -> 49560 | F9: 验收标准的唯一来源
A10: 4 | B10: 数据与知识资产建设 | C10: 语料清洗与结构化、标注、权限梳理、检索切分与索引构建 | D10: 一次性 | E10: ='成本测算'!$G$27/(1-'参数'!$B$9) -> 81608.8 | F10: 工作量波动最大项
A11: 5 | B11: 集成与工程实施 | C11: 与既有系统（ERP/MES/工单）对接、环境适配、私有化部署；含差旅驻场 | D11: 一次性 | E11: ='成本测算'!$G$28/(1-'参数'!$B$9) -> 135794.4 | F11: 老系统对接成本最高
A12: 6 | B12: 评测与安全合规 | C12: 幻觉测试、越权与提示词注入测试、审计留痕、数据分级、密评/等保配合 | D12: 一次性 | E12: ='成本测算'!$G$29/(1-'参数'!$B$9) -> 39648 | F12: 不可删项
A13: 7 | B13: 算力与模型调用 | C13: 推理 Token、向量库/检索服务、第三方 API（OCR/短信），试点期 6 个月 | D13: 按量预留 | E13: ='成本测算'!$G$30/(1-'参数'!$B$9) -> 34692 | F13: 超出封顶需书面确认
A14: 8 | B14: 部署上线与培训 | C14: 生产环境发布、管理员与终端用户培训各 1 场、操作手册、应急预案 | D14: 一次性 | E14: ='成本测算'!$G$31/(1-'参数'!$B$9) -> 21145.6 | F14: 含客户方适应成本
A15: 9 | B15: 运维与持续优化 | C15: 3 个月质保：监控告警、模型与 Prompt 迭代、故障响应（≤4 小时） | D15: 季度 | E15: ='成本测算'!$G$32/(1-'参数'!$B$9) -> 26432 | F15: 到期可续订
A16: 基础费小计（含保底毛利，非按人天计价） | D16: ="总投入 "&'成本测算'!$D$20&" 人天" -> 总投入 118 人天 | E16: =SUM(E7:E15) -> 461568.8
A18: 二、效果浮动 结果红利（公式事前写死，签约即锁定，详见《效果浮动》页）
A19: 序号 | B19: 浮动指标 | C19: 结算口径 | D19: 权重 | E19: 浮动上限（元） | F19: 备注
A20: 1 | B20: 使用渗透率 | C20: 试点范围周活用户数 ÷ 目标用户数，反映「愿不愿意用」 | D20: 0.3 | E20: ='成本测算'!$D$44*$D20 -> 46156.88 | F20: 观察期月度均值
A21: 2 | B21: 自助闭环率 | C21: 未转人工且 24 小时内无重复追问的会话数 ÷ 总会话数，反映「用得成不成」 | D21: 0.4 | E21: ='成本测算'!$D$44*$D21 -> 61542.507 | F21: 剔除故障时段
A22: 3 | B22: 关键流程替代率 | C22: 经助手完成并落库的设备申请/预约数 ÷ 该流程总申请数，反映「替不替代」 | D22: 0.3 | E22: ='成本测算'!$D$44*$D22 -> 46156.88 | F22: 以业务库来源字段统计
A23: 浮动池小计（低于起付线则为 0，不倒扣基础费） | D23: =SUM(D20:D22) -> 1 | E23: =SUM(E20:E22) -> 153856.27 | F23: 约占合同额 25%
A24: 合同金额上限（基础费 + 浮动池） | E24: =E16+E23 -> 615425.07 | F24: 未含增值税
A26: 三、报价说明（建议原文写入合同）
A27: 1. 「人天仅为成本口径，不作为定价口径。」本单按交付范围与验收标准计价，不按工时结算；如需按工时结算，另签人天框架协议。
A28: 2. 「范围以本单《交付清单》为准，清单外需求走变更流程。」变更须先评估工时与影响并书面留痕，累计变更金额超过合同额 20% 时触发合同复核。
A29: 3. 「本报价已包含：售前调研、数据与知识资产建设、评测与安全合规、上线培训、质保期运维。」九个成本科目已逐条对应到上方条目，无隐含项。
A30: 4. 「效果浮动公式、指标口径与数据来源在签约前书面确认，观察期内不得单方修改。」结算以双方共管看板数据为唯一依据。
A32: 四、付款节点
A33: 节点 | C33: 触发条件 | D33: 比例 | E33: 金额（元） | F33: 说明
A34: 首付款 | C34: 合同签订并收到发票后 5 个工作日内 | D34: 0.3 | E34: =$E$16*D34 -> 138470.64 | F34: 覆盖售前与启动投入
A35: 上线款 | C35: UAT 通过并签署《上线验收单》后 10 个工作日内 | D35: 0.4 | E35: =$E$16*D35 -> 184627.52 | F35: 对应交付清单第 1–9 项
A36: 质保款 | C36: 质保期满（上线后 3 个月）并签署《质保确认单》 | D36: 0.3 | E36: =$E$16*D36 -> 138470.64 | F36: 对应交付清单第 10 项
A37: 效果结算款 | C37: 观察期（6 个月）结束后 15 个工作日内按公式结算 | D37: — | E37: =$E$23 -> 153856.27 | F37: 0 ～ 上限，见《效果浮动》页
A38: 合计（基础费 100%，浮动另计） | C38: 详见合同付款条款 | D38: =SUM(D34:D36) -> 1 | E38: =SUM(E34:E37) -> 615425.07 | F38: 0 ～ 上限区间
A40: 五、签署
A41: 甲方（盖章）
A42: 乙方（盖章）
A43: 签署日期
A45: 备注：本报价未含增值税，税率按国家规定另计；如涉及私有化部署所需的 GPU 服务器、网络与机房资源，由甲方提供或另行报价；本报价自出具日起 30 天内有效。

Sheet 效果浮动
A1: 效果浮动条款 — 结算口径与公式（作为合同附件签署）
A2: 浮动池上限、起付线与封顶线均取自「参数」页；本页公式为结算唯一口径，签约后不得单方修改。
A4: 一、浮动指标（权重合计 100%，三项分别计算，互不抵扣）
A5: 序号 | B5: 浮动指标 | C5: 定义与计算口径 | D5: 数据来源 | E5: 基线值 | F5: 目标值 | G5: 实际值 | H5: 达成率 | I5: 计费系数 | J5: 权重 | K5: 浮动金额（元）
A6: 1 | B6: 使用渗透率 | C6: 观察期内周活用户数的月度均值 ÷ 试点范围目标用户数 | D6: 系统埋点（登录 + 有效会话） | E6: 0 | F6: 0.6 | H6: =IF(OR($F6="",$F6=0,$G6=""),"",$G6/$F6) | I6: =IF($H6="",0,MEDIAN(0,($H6-'参数'!$B$12)/('参数'!$B$13-'参数'!$B$12),1)) -> 0 | J6: 0.3 | K6: =IF($J6="",0,'成本测算'!$D$44*$J6*$I6) -> 0
A7: 2 | B7: 自助闭环率 | C7: 未转人工、且 24 小时内无重复追问的会话数 ÷ 总会话数 | D7: 会话日志 + 转人工标记 | E7: 0 | F7: 0.75 | H7: =IF(OR($F7="",$F7=0,$G7=""),"",$G7/$F7) | I7: =IF($H7="",0,MEDIAN(0,($H7-'参数'!$B$12)/('参数'!$B$13-'参数'!$B$12),1)) -> 0 | J7: 0.4 | K7: =IF($J7="",0,'成本测算'!$D$44*$J7*$I7) -> 0
A8: 3 | B8: 关键流程替代率 | C8: 经助手完成并成功落库的设备申请/预约数 ÷ 该流程总申请数 | D8: 业务库申请表来源字段 | E8: 0 | F8: 0.4 | H8: =IF(OR($F8="",$F8=0,$G8=""),"",$G8/$F8) | I8: =IF($H8="",0,MEDIAN(0,($H8-'参数'!$B$12)/('参数'!$B$13-'参数'!$B$12),1)) -> 0 | J8: 0.3 | K8: =IF($J8="",0,'成本测算'!$D$44*$J8*$I8) -> 0
A9: 合计（实际值待观察期结束后填写） | J9: =SUM(J6:J8) -> 1 | K9: =SUM(K6:K8) -> 0
A10: 计费系数 = MEDIAN(0,(达成率 − 起付线) ÷ (封顶线 − 起付线),1)；达成率 = 实际值 ÷ 目标值。三项指标独立结算后加总，总额不超过浮动池上限。
A12: 二、红线项（不达标从基础费扣减，与浮动池独立计算）
A13: 序号 | B13: 红线项 | C13: 达标标准 | D13: 检测方式 | E13: 未达标扣款 | F13: 说明
A14: 1 | B14: 越权访问拦截 | C14: 100%：任何一次跨用户数据可见即判定不达标 | D14: 每季度抽样 30 次跨账号越权尝试 | E14: 0.1 | F14: 最严重的一项，直接触及数据合规底线
A15: 2 | B15: 事实错误率 | C15: ≤ 2%：抽检 200 条回答，事实性错误不超过 4 条 | D15: 双方各独立抽检 100 条并交叉复核 | E15: 0.05 | F15: 误命中、编造库存/工号均计入
A16: 3 | B16: 高危指令拦截 | C16: 100%：诱导越权或绕过确认直接写库的指令必须全拦截 | D16: 注入用例库 ≥ 30 条，每次迭代回归 | E16: 0.05 | F16: 含「别走草稿直接提交」类诱导
A17: 4 | B17: 服务可用性 | C17: ≥ 99.5%：连续 3 日低于阈值即触发 | D17: 监控系统月度统计，剔除计划内停机 | E17: 0.05 | F17: 不含乙方提前 48 小时公告的维护窗口
A18: 红线扣款按基础费比例计，累计不超过基础费的 20%；触发扣款不免除乙方继续交付与整改的义务，整改期最长 30 日，逾期按合同违约条款处理。
A20: 三、浮动结算阶梯（客户可自行代入，算不出数的计价方式在 AI 时代一定会被压价）
A21: 达成率 | B21: 计费系数 | C21: 结算金额（元） | D21: 说明
A22: 0.7 | B22: =MEDIAN(0,($A22-'参数'!$B$12)/('参数'!$B$13-'参数'!$B$12),1) -> 0 | C22: ='成本测算'!$D$44*$B22 -> 0 | D22: 起付线：浮动为 0，仅结算基础费
A23: 0.8 | B23: =MEDIAN(0,($A23-'参数'!$B$12)/('参数'!$B$13-'参数'!$B$12),1) -> 0.2 | C23: ='成本测算'!$D$44*$B23 -> 30771.253 | D23: 拿到浮动池的 20%
A24: 0.9 | B24: =MEDIAN(0,($A24-'参数'!$B$12)/('参数'!$B$13-'参数'!$B$12),1) -> 0.4 | C24: ='成本测算'!$D$44*$B24 -> 61542.507 | D24: 拿到浮动池的 40%
A25: 1 | B25: =MEDIAN(0,($A25-'参数'!$B$12)/('参数'!$B$13-'参数'!$B$12),1) -> 0.6 | C25: ='成本测算'!$D$44*$B25 -> 92313.76 | D25: 达到承诺目标，拿到浮动池的 60%
A26: 1.1 | B26: =MEDIAN(0,($A26-'参数'!$B$12)/('参数'!$B$13-'参数'!$B$12),1) -> 0.8 | C26: ='成本测算'!$D$44*$B26 -> 123085.01 | D26: 拿到浮动池的 80%
A27: 1.2 | B27: =MEDIAN(0,($A27-'参数'!$B$12)/('参数'!$B$13-'参数'!$B$12),1) -> 1 | C27: ='成本测算'!$D$44*$B27 -> 153856.27 | D27: 封顶线：拿满浮动池 100%
A28: 本表按「三项指标达成率一致」示例；实际结算时逐项代入第 6:8 行，加总后与上表同口径。
A30: 四、结算规则（建议原文写入合同附件）
A31: 1. 结算周期：系统上线并完成 UAT 验收之日起 6 个自然月为效果观察期；观察期结束后 15 个工作日内完成结算，随最后一期款项支付。
A32: 2. 数据来源：三项指标均由系统埋点自动统计；数据所有权归甲方，乙方拥有读取权限；观察期内双方共管同一块数据看板，看板数据为结算唯一依据。
A33: 3. 归因排除：因甲方未按《交付清单》提供环境、数据或人员配合导致指标未达，经双方书面确认后不计入考核；因甲方业务量本身波动（假期、学期、政策调整）导致的偏差，按可比月份折算。
A34: 4. 口径锁定：观察期内不得单方修改指标定义与计算口径；确需调整的，须双方书面签署补充协议，并同步调整目标值与浮动池金额。
A35: 5. 独立计算：三项指标分别按达成率对应系数结算，互不抵扣；合计金额不超过浮动池上限。
A36: 6. 上下限：浮动结算下限为 0 元，不倒扣基础费；上限为浮动池上限。红线项扣款另计，累计不超过基础费的 20%。
A37: 7. 逾期与终止：甲方逾期付款超过 30 日的，乙方有权暂停服务且观察期顺延；合同提前终止的，浮动池按已履行月份比例折算，不足整月不计。
A39: 五、数据共管与争议处理
A40: 1. 看板权限：甲方管理员与乙方项目经理各持独立账号，所有查询与导出操作留痕；任一方不得单方修改历史数据。
A41: 2. 抽样复核：甲方有权每季度对埋点数据抽样复核 1 次，抽样比例不低于 5%，乙方须提供复核所需的原始日志。
A42: 3. 争议处理：对某一指标存在争议的，先以原始埋点日志复核；仍不一致的，由双方各指定 1 名技术人员在 5 个工作日内出具结论；仍不能达成一致的，按合同争议条款处理。

Sheet 交付清单
A1: 交付清单 — 报价范围的唯一依据（清单外需求一律走变更流程）
A2: 先有清单，才有价格。报价单里每个金额都能在本清单找到对应的可核验交付物与验收标准。
A4: 序号 | B4: 交付阶段 | C4: 交付物 | D4: 范围与数量 | E4: 验收标准 | F4: 对应科目
A5: 1 | B5: 第 2 周 | C5: 场景清单与诊断报告 | D5: 覆盖 4 个核心场景，含现状与目标差距、数据可行性判断、优先级排序 | E5: 4 个场景均给出可落地或明确不可行的结论，甲方业务负责人签字确认 | F5: 02 / 03
A6: 2 | B6: 第 3 周 | C6: 方案与架构说明书 | D6: 技术选型、数据流图、权限与安全架构、部署拓扑、评测集设计说明 | E6: 通过甲方技术评审会，评审意见全部闭环 | F6: 03
A7: 3 | B7: 第 5 周 | C7: 知识资产包 | D7: 结构化 FAQ ≥ 200 条、文档切片 ≥ 800 段、元数据与权限标注规范 1 份 | E7: 抽查 50 条，问答可溯源率 ≥ 95% | F7: 04
A8: 4 | B8: 第 6 周 | C8: 可运行系统（UAT 版） | D8: 4 个场景端到端可用；工具调用、权限隔离、草稿确认机制完整实现 | E8: 工具选择准确率 ≥ 90%；越权路径 100% 拦截 | F8: 05
A9: 5 | B9: 第 6 周 | C9: 评测集（Golden Set） | D9: ≥ 60 条，覆盖工具选择、拒答、越权、诱导、注入、多轮六类 | E9: 六类各 ≥ 8 条，双方确认后冻结版本号 | F9: 06
A10: 6 | B10: 第 7 周 | C10: 评测报告 | D10: 准确率、幻觉率、越权拦截率三项实测结果与失败样本分析 | E10: 准确率 ≥ 90%；越权与注入拦截 100% | F10: 06
A11: 7 | B11: 第 7 周 | C11: 安全与合规清单 | D11: 数据分级、脱敏规则、审计留痕方案、密评/等保配合说明各 1 份 | E11: 甲方信息安全部门会签 | F11: 06
A12: 8 | B12: 第 7 周 | C12: 上线与运维手册 | D12: 部署手册、操作手册、应急预案各 1 份 | E12: 按手册在演练环境独立复现一次部署成功 | F12: 08
A13: 9 | B13: 第 7 周 | C13: 培训与交付 | D13: 管理员 1 场 + 终端用户 1 场，各 2 小时，含课件与录屏 | E13: 参训人员实操通过率 ≥ 80% | F13: 08
A14: 10 | B14: 第 8 周起 3 个月 | C14: 质保期运维 | D14: 监控告警、月度迭代 1 次、故障响应 ≤ 4 小时 | E14: 月度运维报告 3 份，无未闭环 P1 故障 | F14: 09
A17: 变更条款
A18: 任何不在本清单内的功能、场景或数据范围，须先由乙方出具《变更评估单》（工时、影响范围、对验收标准的影响），经双方书面确认后方可执行；累计变更金额超过合同额 20% 时触发合同复核。口头或聊天记录中的确认不生效。

Sheet 参数
A1: 参数中心（全表唯一入口）
A2: 改动本页任一数值，「成本测算」「报价单」「效果浮动」三页自动联动。灰底为可改输入，白底为说明。
A4: 一、报价参数
A5: 参数 | B5: 取值 | C5: 说明
A6: 管理分摊率 | B6: 0.18 | C6: 销售、行政、房租、设备等公司级费用分摊
A7: 风险准备率 | B7: 0.12 | C7: 需求变更、跨期、验收争议的缓冲
A8: 目标毛利率 | B8: 0.4 | C8: 效果浮动拿满时的综合毛利率
A9: 基础费保底毛利率 | B9: 0.2 | C9: 效果全未达时的最低毛利，务必大于 0
A10: 质保期（月） | B10: 3 | C10: 上线后免费运维期，含在基础费内
A11: 效果观察期（月） | B11: 6 | C11: 浮动结算的计量周期
A12: 浮动起付达成率 | B12: 0.7 | C12: 低于此值浮动为 0，仅结算基础费
A13: 浮动封顶达成率 | B13: 1.2 | C13: 达到此值拿满浮动池
A14: 红线扣款上限 | B14: 0.2 | C14: 红线扣款累计不超过基础费的比例
A16: 二、角色内部成本单价（成本口径，非对客单价）
A17: 角色 | B17: 成本单价（元/人天） | C17: 说明
A18: 交付负责人 | B18: 2600 | C18: FDE Lead，对方案与验收负责
A19: 诊断与方案 | B19: 2400 | C19: 场景诊断、架构与评测集设计
A20: 数据与知识工程 | B20: 1900 | C20: 清洗、标注、检索切分、索引
A21: 集成开发 | B21: 2100 | C21: 系统对接、私有化部署
A22: 评测与安全 | B22: 2000 | C22: 幻觉/越权/注入测试、合规
A23: 部署培训与运维 | B23: 1600 | C23: 发布、培训、质保期运维
A25: 提醒：管理分摊率、风险准备率、目标毛利率三套参数因公司阶段与客户类型差异极大，不要直接沿用示例值——先用本公司近 3 个项目的实际数据倒推一遍，再定稿。

Sheet 成本测算
A1: 成本测算（内部）— 按九科目归集，请勿随报价单交付客户
A2: 推导顺序：交付清单 → 工时分解 → 直接成本 → 分摊与风险 → 报价。顺序不可倒：先谈定范围再填工时，反过来就是「报价凑数」，客户一问就崩。
A4: 一、工时分解与直接成本（按角色 × 阶段填表）
A5: 序号 | B5: 成本科目 | C5: 角色 / 费用项 | D5: 人天 | E5: 成本单价（元/人天） | F5: 人力成本（元） | G5: 直接成本（元） | H5: 说明
A6: 1 | B6: 01 售前与机会成本 | C6: 交付负责人 | D6: 4 | E6: =IF($D6="","",VLOOKUP($C6,'参数'!$A$18:$B$23,2,FALSE)) -> 2600 | F6: =IF($D6="","",$D6*$E6) -> 10400 | H6: 标书、方案、投标材料（未中标也照花）
A7: 2 | B7: 01 售前与机会成本 | C7: 诊断与方案 | D7: 4 | E7: =IF($D7="","",VLOOKUP($C7,'参数'!$A$18:$B$23,2,FALSE)) -> 2400 | F7: =IF($D7="","",$D7*$E7) -> 9600 | H7: POC 演示与驻场调研
A8: 3 | B8: 02 诊断与场景梳理 | C8: 诊断与方案 | D8: 10 | E8: =IF($D8="","",VLOOKUP($C8,'参数'!$A$18:$B$23,2,FALSE)) -> 2400 | F8: =IF($D8="","",$D8*$E8) -> 24000 | H8: 现状诊断、场景筛选、可行性结论
A9: 4 | B9: 03 方案与架构设计 | C9: 交付负责人 | D9: 6 | E9: =IF($D9="","",VLOOKUP($C9,'参数'!$A$18:$B$23,2,FALSE)) -> 2600 | F9: =IF($D9="","",$D9*$E9) -> 15600 | H9: 技术选型、权限模型、验收标准定义
A10: 5 | B10: 03 方案与架构设计 | C10: 诊断与方案 | D10: 6 | E10: =IF($D10="","",VLOOKUP($C10,'参数'!$A$18:$B$23,2,FALSE)) -> 2400 | F10: =IF($D10="","",$D10*$E10) -> 14400 | H10: 数据流设计、评测集（Golden Set）设计
A11: 6 | B11: 04 数据与知识资产建设 | C11: 数据与知识工程 | D11: 26 | E11: =IF($D11="","",VLOOKUP($C11,'参数'!$A$18:$B$23,2,FALSE)) -> 1900 | F11: =IF($D11="","",$D11*$E11) -> 49400 | H11: 清洗、结构化、标注、权限梳理、检索切分
A12: 7 | B12: 05 集成与工程实施 | C12: 集成开发 | D12: 32 | E12: =IF($D12="","",VLOOKUP($C12,'参数'!$A$18:$B$23,2,FALSE)) -> 2100 | F12: =IF($D12="","",$D12*$E12) -> 67200 | H12: 既有系统对接、环境适配、私有化部署
A13: 8 | B13: 06 评测与安全合规 | C13: 评测与安全 | D13: 12 | E13: =IF($D13="","",VLOOKUP($C13,'参数'!$A$18:$B$23,2,FALSE)) -> 2000 | F13: =IF($D13="","",$D13*$E13) -> 24000 | H13: 幻觉测试、越权与注入测试、审计留痕
A14: 9 | B14: 08 部署上线与培训 | C14: 部署培训与运维 | D14: 8 | E14: =IF($D14="","",VLOOKUP($C14,'参数'!$A$18:$B$23,2,FALSE)) -> 1600 | F14: =IF($D14="","",$D14*$E14) -> 12800 | H14: 生产发布、培训 2 场、手册与应急预案
A15: 10 | B15: 09 运维与持续优化 | C15: 部署培训与运维 | D15: 10 | E15: =IF($D15="","",VLOOKUP($C15,'参数'!$A$18:$B$23,2,FALSE)) -> 1600 | F15: =IF($D15="","",$D15*$E15) -> 16000 | H15: 3 个月质保：监控、迭代、故障响应
A16: 11 | B16: 07 算力与模型调用 | C16: 推理 Token（试点 6 个月） | G16: 12000 | H16: 按实际调用量，预留 30% 余量
A17: 12 | B17: 07 算力与模型调用 | C17: 向量库 / 检索服务 | G17: 6000 | H17: 托管向量库年费摊入试点期
A18: 13 | B18: 07 算力与模型调用 | C18: 第三方 API（OCR / 短信） | G18: 3000 | H18: 按调用量结算
A19: 14 | B19: 05 集成与工程实施 | C19: 差旅与驻场 | G19: 15000 | H19: 按 6 次往返估算
A20: 合计（总投入人天 / 直接成本） | D20: =SUM(D6:D19) -> 118 | F20: =SUM(F6:F19) -> 243400 | G20: =SUM(G6:G19) -> 36000 | H20: 人天仅作成本口径，不作对外定价口径
A22: 二、按九科目归集（每科目 = 人力 + 直接成本，再乘分摊与风险）
A23: 序号 | B23: 成本科目 | C23: 人力成本（元） | D23: 直接成本（元） | E23: 小计（元） | F23: 分摊与风险（元） | G23: 科目全成本（元） | H23: 备注
A24: 1 | B24: 01 售前与机会成本 | C24: =SUMIF($B$6:$B$19,$B24,$F$6:$F$19) -> 20000 | D24: =SUMIF($B$6:$B$19,$B24,$G$6:$G$19) -> 0 | E24: =$C24+$D24 -> 20000 | F24: =IF($E24="","",$E24*(1+'参数'!$B$6)*(1+'参数'!$B$7)-$E24) -> 6432 | G24: =IF($E24="","",$E24+$F24) -> 26432 | H24: 含未中标成本，最易漏记
A25: 2 | B25: 02 诊断与场景梳理 | C25: =SUMIF($B$6:$B$19,$B25,$F$6:$F$19) -> 24000 | D25: =SUMIF($B$6:$B$19,$B25,$G$6:$G$19) -> 0 | E25: =$C25+$D25 -> 24000 | F25: =IF($E25="","",$E25*(1+'参数'!$B$6)*(1+'参数'!$B$7)-$E25) -> 7718.4 | G25: =IF($E25="","",$E25+$F25) -> 31718.4 | H25: 核心工时，最难被认可价值
A26: 3 | B26: 03 方案与架构设计 | C26: =SUMIF($B$6:$B$19,$B26,$F$6:$F$19) -> 30000 | D26: =SUMIF($B$6:$B$19,$B26,$G$6:$G$19) -> 0 | E26: =$C26+$D26 -> 30000 | F26: =IF($E26="","",$E26*(1+'参数'!$B$6)*(1+'参数'!$B$7)-$E26) -> 9648 | G26: =IF($E26="","",$E26+$F26) -> 39648 | H26: 验收标准的源头
A27: 4 | B27: 04 数据与知识资产建设 | C27: =SUMIF($B$6:$B$19,$B27,$F$6:$F$19) -> 49400 | D27: =SUMIF($B$6:$B$19,$B27,$G$6:$G$19) -> 0 | E27: =$C27+$D27 -> 49400 | F27: =IF($E27="","",$E27*(1+'参数'!$B$6)*(1+'参数'!$B$7)-$E27) -> 15887.04 | G27: =IF($E27="","",$E27+$F27) -> 65287.04 | H27: 波动最大，Token 空转的真正源头
A28: 5 | B28: 05 集成与工程实施 | C28: =SUMIF($B$6:$B$19,$B28,$F$6:$F$19) -> 67200 | D28: =SUMIF($B$6:$B$19,$B28,$G$6:$G$19) -> 15000 | E28: =$C28+$D28 -> 82200 | F28: =IF($E28="","",$E28*(1+'参数'!$B$6)*(1+'参数'!$B$7)-$E28) -> 26435.52 | G28: =IF($E28="","",$E28+$F28) -> 108635.52 | H28: 老系统对接成本最高
A29: 6 | B29: 06 评测与安全合规 | C29: =SUMIF($B$6:$B$19,$B29,$F$6:$F$19) -> 24000 | D29: =SUMIF($B$6:$B$19,$B29,$G$6:$G$19) -> 0 | E29: =$C29+$D29 -> 24000 | F29: =IF($E29="","",$E29*(1+'参数'!$B$6)*(1+'参数'!$B$7)-$E29) -> 7718.4 | G29: =IF($E29="","",$E29+$F29) -> 31718.4 | H29: 不可删项，事故成本更高
A30: 7 | B30: 07 算力与模型调用 | C30: =SUMIF($B$6:$B$19,$B30,$F$6:$F$19) -> 0 | D30: =SUMIF($B$6:$B$19,$B30,$G$6:$G$19) -> 21000 | E30: =$C30+$D30 -> 21000 | F30: =IF($E30="","",$E30*(1+'参数'!$B$6)*(1+'参数'!$B$7)-$E30) -> 6753.6 | G30: =IF($E30="","",$E30+$F30) -> 27753.6 | H30: 按量预留，须设封顶
A31: 8 | B31: 08 部署上线与培训 | C31: =SUMIF($B$6:$B$19,$B31,$F$6:$F$19) -> 12800 | D31: =SUMIF($B$6:$B$19,$B31,$G$6:$G$19) -> 0 | E31: =$C31+$D31 -> 12800 | F31: =IF($E31="","",$E31*(1+'参数'!$B$6)*(1+'参数'!$B$7)-$E31) -> 4116.48 | G31: =IF($E31="","",$E31+$F31) -> 16916.48 | H31: 客户方适应成本在此
A32: 9 | B32: 09 运维与持续优化 | C32: =SUMIF($B$6:$B$19,$B32,$F$6:$F$19) -> 16000 | D32: =SUMIF($B$6:$B$19,$B32,$G$6:$G$19) -> 0 | E32: =$C32+$D32 -> 16000 | F32: =IF($E32="","",$E32*(1+'参数'!$B$6)*(1+'参数'!$B$7)-$E32) -> 5145.6 | G32: =IF($E32="","",$E32+$F32) -> 21145.6 | H32: 从一次性收入走向持续收入
A33: 合计 | C33: =SUM(C24:C32) -> 243400 | D33: =SUM(D24:D32) -> 36000 | E33: =SUM(E24:E32) -> 279400 | F33: =SUM(F24:F32) -> 89855.04 | G33: =SUM(G24:G32) -> 369255.04 | H33: 应等于下方④全成本
A34: =IF(ROUND($G$33-$D$41,2)=0,"✓ 校验通过：科目归集合计 = 推导全成本","✗ 不一致，请检查第 6:19 行科目名是否拼写一致") -> ✓ 校验通过：科目归集合计 = 推导全成本
A36: 三、全成本与报价推导（口径链：工时 → 直接成本 → 分摊与风险 → 报价）
B37: 步骤 | C37: 计算式 | D37: 金额（元） | E37: 说明
A38: ① | B38: 直接成本合计 | C38: Σ(人天 × 成本单价) + 算力/第三方 + 差旅驻场 | D38: =F20+G20 -> 279400 | E38: 人力与直接成本都在这，未加任何系数
A39: ② | B39: 管理分摊 | C39: ① × 管理分摊率 | D39: =D38*'参数'!$B$6 -> 50292 | E39: 销售、行政、房租、设备：不摊进去等于自己扛
A40: ③ | B40: 风险准备 | C40: (① + ②) × 风险准备率 | D40: =(D38+D39)*'参数'!$B$7 -> 39563.04 | E40: 需求变更、跨期、验收争议的缓冲
A41: ④ | B41: 全成本 | C41: ① + ② + ③ | D41: =SUM(D38:D40) -> 369255.04 | E41: 真正的成本线，低于此价即为亏损项目
A42: ⑤ | B42: 基础费（对客） | C42: ④ ÷ (1 − 基础费保底毛利率) | D42: =D41/(1-'参数'!$B$9) -> 461568.8 | E42: 效果全未达时也能保住的底价
A43: ⑥ | B43: 目标总报价 | C43: ④ ÷ (1 − 目标毛利率) | D43: =D41/(1-'参数'!$B$8) -> 615425.07 | E43: 浮动拿满时的合同总额
...
